Workbook
Name ConstGrowth: Valuation!$C$28
Name DiscountRate: Valuation!$C$31
Name ExitMultiple: Valuation!$C$32
Name FcffValuePerShare: 'FCFF DCF'!$C$84
Name GrowthMode: Valuation!$C$27
Name MarginEnd: Valuation!$C$30
Name MarginStart: Valuation!$C$29
Name NetAdj: Valuation!$C$33
Name Price: Valuation!$C$25
Name PriceDate: Valuation!$C$34
Name Shares: Valuation!$C$26
Name StubFraction: Valuation!$C$35
Name ValuePerShare: Valuation!$C$66

Sheet FCFF DCF
B2: Titan Company Ltd (NSE: TITAN): Free Cash Flow (FCFF) DCF
B3: Prepared by Daksh Chaudhary · 4-Oct-2026 · ₹ crore unless stated · same revenue path, price date and cost of equity as the Valuation sheet · Blue = input
B5: 1 INPUTS
B6: Share price (₹) | C6: =Price -> 4515.7 | D6: Linked to the Valuation sheet
B7: Price date | C7: =PriceDate -> 46296 | D7: NSE close; the stub runs from here to 31-Mar-2027
B8: Diluted shares (mn) | C8: =Shares -> 890
B9: Tax rate | C9: 0.2517 | D9: Indian corporate rate under the new regime (25.17%)
B10: Cost of equity | C10: =DiscountRate -> 0.1026 | D10: Linked to the Valuation sheet
B11: Gold on loan treated as | C11: Operating | D11: Operating (base) or Debt
B12: Gold-loan fee if operating (my assumption) | C12: 0.02 | D12: Yearly cost, deducted from EBIT
B13: EBIT margin, before gold-loan fee | C13: =AVERAGE(E37:I37) -> 0.09451628 | D13: FY2022-FY2026 average
B14: D&A, % of sales | C14: =AVERAGE(E40:I40) -> 0.011409878 | D14: FY2022-FY2026 average
B15: Capex, % of sales | C15: =AVERAGE(E39:I39) -> 0.024809174 | D15: FY2022-FY2026 average
B16: Working capital, % of sales | C16: =IF($C$11="Debt",AVERAGE(G42:I42),AVERAGE(G44:I44)) -> 0.23829195 | D16: FY2024-FY2026 average (the years with a gold-on-loan split)
B17: Terminal growth | C17: 0.06 | D17: Nominal, in rupees, after FY2042
B18: WACC override (blank = computed) | D18: Used by the sensitivity table
B19: Share of FY2027 still ahead (stub) | C19: =StubFraction -> 0.49589041
B21: 2 HISTORY (consolidated, ₹ crore; Screener.in, gold on loan from ICICI Direct's Q4FY26 update)
B22: Fiscal year | D22: 2021 | E22: 2022 | F22: 2023 | G22: 2024 | H22: 2025 | I22: 2026
B23: Sales | D23: 21644 | E23: 28799 | F23: 40575 | G23: 51084 | H23: 60456 | I23: 87584
B24: Profit before tax | D24: 1327 | E24: 2904 | F24: 4447 | G24: 4623 | H24: 4535 | I24: 6801
B25: Interest | D25: 203 | E25: 218 | F25: 300 | G25: 619 | H25: 953 | I25: 1180
B26: Other income | D26: 180 | E26: 177 | F26: 306 | G26: 534 | H26: 487 | I26: 450
B27: Depreciation | D27: 375 | E27: 399 | F27: 441 | G27: 584 | H27: 693 | I27: 826
B28: Net block | D28: 2523 | E28: 2544 | F28: 2998 | G28: 3709 | H28: 4062 | I28: 6878
B29: Capital work in progress | D29: 32 | E29: 85 | F29: 144 | G29: 97 | H29: 105 | I29: 163
B30: Other assets (incl. inventory, receivables, cash) | D30: 11065 | E30: 18265 | F30: 21363 | G30: 25396 | H30: 34490 | I30: 50014
B31: Other liabilities | D31: 3309 | E31: 4610 | F31: 5802 | G31: 6626 | H31: 8244 | I31: 14237
B32: Cash & bank | D32: 560 | E32: 1573 | F32: 1343 | G32: 1526 | H32: 1584 | I32: 1917
B33: Borrowings (incl. gold on loan and leases) | D33: 5638 | E33: 7275 | F33: 9367 | G33: 15528 | H33: 20777 | I33: 30621
B34: Gold on loan | G34: 5341 | H34: 7810 | I34: 16070
B36: EBIT = PBT + interest − other income | D36: =D24+D25-D26 -> 1350 | E36: =E24+E25-E26 -> 2945 | F36: =F24+F25-F26 -> 4441 | G36: =G24+G25-G26 -> 4708 | H36: =H24+H25-H26 -> 5001 | I36: =I24+I25-I26 -> 7531
B37: EBIT margin | D37: =D36/D23 -> 0.062372944 | E37: =E36/E23 -> 0.1022605 | F37: =F36/F23 -> 0.10945163 | G37: =G36/G23 -> 0.092161929 | H37: =H36/H23 -> 0.082721318 | I37: =I36/I23 -> 0.085986025
B38: Capex = Δ net block + Δ CWIP + depreciation | E38: =E28-D28+E29-D29+E27 -> 473 | F38: =F28-E28+F29-E29+F27 -> 954 | G38: =G28-F28+G29-F29+G27 -> 1248 | H38: =H28-G28+H29-G29+H27 -> 1054 | I38: =I28-H28+I29-H29+I27 -> 3700
B39: Capex, % of sales | E39: =E38/E23 -> 0.016424181 | F39: =F38/F23 -> 0.023512015 | G39: =G38/G23 -> 0.02443035 | H39: =H38/H23 -> 0.017434167 | I39: =I38/I23 -> 0.042245159
B40: D&A, % of sales | D40: =D27/D23 -> 0.017325818 | E40: =E27/E23 -> 0.013854648 | F40: =F27/F23 -> 0.010868762 | G40: =G27/G23 -> 0.011432151 | H40: =H27/H23 -> 0.011462882 | I40: =I27/I23 -> 0.0094309463
B41: Working capital, gold on loan as debt = other assets − cash − other liabilities | D41: =D30-D32-D31 -> 7196 | E41: =E30-E32-E31 -> 12082 | F41: =F30-F32-F31 -> 14218 | G41: =G30-G32-G31 -> 17244 | H41: =H30-H32-H31 -> 24662 | I41: =I30-I32-I31 -> 33860
B42: % of sales | D42: =D41/D23 -> 0.33247089 | E42: =E41/E23 -> 0.41952846 | F42: =F41/F23 -> 0.35041282 | G42: =G41/G23 -> 0.33756166 | H42: =H41/H23 -> 0.40793304 | I42: =I41/I23 -> 0.38660029
B43: Working capital, gold on loan as operating = above − gold on loan | G43: =G41-G34 -> 11903 | H43: =H41-H34 -> 16852 | I43: =I41-I34 -> 17790
B44: % of sales | G44: =G43/G23 -> 0.23300838 | H44: =H43/H23 -> 0.27874818 | I44: =I43/I23 -> 0.20311929
...

Sheet Valuation
B2: Titan Company Ltd (NSE: TITAN): Discounted-Earnings Valuation
B3: Prepared by Daksh Chaudhary · updated 4-Oct-2026 · Base case, via Net Income · ₹ bn unless stated
B5: VALUATION ASSUMPTIONS
B6: Revenue Growth | C6: =(AC41/M41)^(1/AC40)-1 -> 0.12604317
B7: Net Margin | C7: =TEXT(MarginStart,"0.0%")&" → "&TEXT(MarginEnd,"0.0%") -> 6.7% → 6.6%
B8: Forecast Period | C8: =(AC40-1)&" years" -> 15 years
B10: MODEL SETTINGS
B11: Template | C11: via Net Income
B12: Discount Rate | C12: =DiscountRate -> 0.1026
B13: Exit Multiple | C13: =ExitMultiple -> 26.522648
B15: VALUATION RESULT
B16: VALUE PER SHARE
B17: =ValuePerShare -> 4057.5127 | C17: =C69 -> Overvaluation 10%
B18: ="vs. market price "&TEXT(Price,"#,##0.0")&" INR · value is "&TEXT(ABS(C68),"0.0%")&IF(C68<0," below"," above")&" the price" -> vs. market price 4,515.7 INR · value is 10.1% below the price
B20: Blue = input | Black = formula | Green = link to Data sheet
B24: 1 INPUTS & ASSUMPTIONS
B25: Current share price (₹) | C25: 4515.7 | D25: Last close as of 1-Oct-2026 (NSE: TITAN)
B26: Diluted shares outstanding (mn) | C26: 890 | D26: Diluted share count (basic ≈ 887.8 mn)
B27: Revenue growth mode | C27: Base case (per year) | D27: Base case = per-year path in row 43; Constant CAGR = C28 in every year
B28: Constant revenue growth (CAGR mode only) | C28: 0.126 | D28: Used only in Constant CAGR mode
B29: Net margin, start (fade anchor) | C29: 0.067105625 | D29: Fades along an S-curve to the FY2042 margin
B30: Net margin, end (FY2042) | C30: 0.06628 | D30: Long-term net margin
B31: Discount rate (cost of equity) | C31: 0.1026 | D31: Required return on equity
B32: Exit multiple (P/E on FY2042 net income) | C32: 26.522648 | D32: Terminal P/E applied to FY2042 net income
B33: Net adjustments / equity bridge (₹ bn) | C33: 0 | D33: Cash / debt adjustments (none applied)
B34: Price date (valuation date) | C34: =DATE(2026,10,1) -> 46296 | D34: NSE close used for the price in C25; the stub runs from here to 31-Mar-2027
B35: Share of FY2027 still ahead (stub) | C35: =(DATE(2027,3,31)-C34)/365 -> 0.49589041 | D35: Share of FY2027 net income still ahead of the price date; discount periods = stub, stub + 1, … years
B37: 2 FORECAST (₹ bn; fiscal years end 31 March)
B38: Fiscal year | C38: Unit | D38: 2017 | E38: 2018 | F38: 2019 | G38: 2020 | H38: 2021 | I38: 2022 | J38: 2023 | K38: 2024 | L38: 2025 | M38: 2026 | N38: 2027 | O38: 2028 | P38: 2029 | Q38: 2030 | R38: 2031 | S38: 2032 | T38: 2033 | U38: 2034 | V38: 2035 | W38: 2036 | X38: 2037 | Y38: 2038 | Z38: 2039 | AA38: 2040 | AB38: 2041 | AC38: 2042
B39: Period | D39: Actual | E39: Actual | F39: Actual | G39: Actual | H39: Actual | I39: Actual | J39: Actual | K39: Actual | L39: Actual | M39: Actual | N39: Forecast | O39: Forecast | P39: Forecast | Q39: Forecast | R39: Forecast | S39: Forecast | T39: Forecast | U39: Forecast | V39: Forecast | W39: Forecast | X39: Forecast | Y39: Forecast | Z39: Forecast | AA39: Forecast | AB39: Forecast | AC39: Forecast
B40: Forecast year (t) | N40: 1 | O40: =N40+1 -> 2 | P40: =O40+1 -> 3 | Q40: =P40+1 -> 4 | R40: =Q40+1 -> 5 | S40: =R40+1 -> 6 | T40: =S40+1 -> 7 | U40: =T40+1 -> 8 | V40: =U40+1 -> 9 | ... AC40: =AB40+1 -> 16
B41: Revenue | C41: ₹ bn | D41: =Data!C7/100 -> 133.821 | E41: =Data!C8/100 -> 161.56 | F41: =Data!C9/100 -> 197.785 | G41: =Data!C10/100 -> 210.515 | H41: =Data!C11/100 -> 216.44 | I41: =Data!C12/100 -> 287.99 | J41: =Data!C13/100 -> 405.75 | K41: =Data!C14/100 -> 510.84 | L41: =Data!C15/100 -> 604.56 | M41: =Data!C16/100 -> 875.84 | N41: =M41*(1+N42) -> 1026.4285 | O41: =N41*(1+O42) -> 1207.1746 | P41: =O41*(1+P42) -> 1412.8551 | Q41: =P41*(1+Q42) -> 1651.18 | R41: =Q41*(1+R42) -> 1921.8977 | S41: =R41*(1+S42) -> 2223.1469 | T41: =S41*(1+T42) -> 2551.3032 | U41: =T41*(1+U42) -> 2901.0733 | ... AC41: =AB41*(1+AC42) -> 5852.0147
B42: Revenue growth | C42: % | E42: =IF(D41=0,0,E41/D41-1) -> 0.20728436 | F42: =IF(E41=0,0,F41/E41-1) -> 0.2242201 | G42: =IF(F41=0,0,G41/F41-1) -> 0.064362818 | H42: =IF(G41=0,0,H41/G41-1) -> 0.028145263 | I42: =IF(H41=0,0,I41/H41-1) -> 0.3305766 | J42: =IF(I41=0,0,J41/I41-1) -> 0.40890309 | K42: =IF(J41=0,0,K41/J41-1) -> 0.25900185 | L42: =IF(K41=0,0,L41/K41-1) -> 0.18346253 | M42: =IF(L41=0,0,M41/L41-1) -> 0.44872304 | N42: =IF(GrowthMode="Constant CAGR",ConstGrowth,N43) -> 0.1719361 | O42: =IF(GrowthMode="Constant CAGR",ConstGrowth,O43) -> 0.1760922 | P42: =IF(GrowthMode="Constant CAGR",ConstGrowth,P43) -> 0.17038176 | Q42: =IF(GrowthMode="Constant CAGR",ConstGrowth,Q43) -> 0.1686832 | R42: =IF(GrowthMode="Constant CAGR",ConstGrowth,R43) -> 0.16395411 | S42: =IF(GrowthMode="Constant CAGR",ConstGrowth,S43) -> 0.15674569 | T42: =IF(GrowthMode="Constant CAGR",ConstGrowth,T43) -> 0.14760889 | U42: =IF(GrowthMode="Constant CAGR",ConstGrowth,U43) -> 0.1370947 | ... AC42: =IF(GrowthMode="Constant CAGR",ConstGrowth,AC43) -> 0.06951
B43: Revenue growth, base case (input) | C43: % input | N43: 0.1719361 | O43: 0.1760922 | P43: 0.17038176 | Q43: 0.1686832 | R43: 0.16395411 | S43: 0.15674569 | T43: 0.14760889 | U43: 0.1370947 | V43: 0.12575406 | W43: 0.11413794 | X43: 0.1027973 | Y43: 0.092283105 | Z43: 0.083146315 | AA43: 0.075937893 | AB43: 0.0712088 | AC43: 0.06951
B44: Net margin | C44: % | D44: =IF(D41=0,0,D46/D41) -> 0.053168038 | E44: =IF(E41=0,0,E46/E41) -> 0.069949245 | F44: =IF(F41=0,0,F46/F41) -> 0.070996284 | G44: =IF(G41=0,0,G46/G41) -> 0.071320333 | H44: =IF(H41=0,0,H46/H41) -> 0.044954722 | I44: =IF(I41=0,0,I46/I41) -> 0.075454009 | J44: =IF(J41=0,0,J46/J41) -> 0.080098583 | K44: =IF(K41=0,0,K46/K41) -> 0.068436301 | ... M44: =IF(M41=0,0,M46/M41) -> 0.057921538 | N44: =MarginStart+(MarginEnd-MarginStart)*N45 -> 0.067096353 | O44: =MarginStart+(MarginEnd-MarginStart)*O45 -> 0.067070149 | P44: =MarginStart+(MarginEnd-MarginStart)*P45 -> 0.067029432 | Q44: =MarginStart+(MarginEnd-MarginStart)*Q45 -> 0.066976621 | R44: =MarginStart+(MarginEnd-MarginStart)*R45 -> 0.066914135 | S44: =MarginStart+(MarginEnd-MarginStart)*S45 -> 0.066844392 | T44: =MarginStart+(MarginEnd-MarginStart)*T45 -> 0.066769812 | U44: =MarginStart+(MarginEnd-MarginStart)*U45 -> 0.066692813 | ... AC44: =MarginStart+(MarginEnd-MarginStart)*AC45 -> 0.06628
B45: Margin fade weight (S-curve, 0 → 1) | C45: weight | N45: =3*(N$40/$AC$40)^2-2*(N$40/$AC$40)^3 -> 0.011230469 | O45: =3*(O$40/$AC$40)^2-2*(O$40/$AC$40)^3 -> 0.04296875 | P45: =3*(P$40/$AC$40)^2-2*(P$40/$AC$40)^3 -> 0.092285156 | Q45: =3*(Q$40/$AC$40)^2-2*(Q$40/$AC$40)^3 -> 0.15625 | R45: =3*(R$40/$AC$40)^2-2*(R$40/$AC$40)^3 -> 0.23193359 | S45: =3*(S$40/$AC$40)^2-2*(S$40/$AC$40)^3 -> 0.31640625 | T45: =3*(T$40/$AC$40)^2-2*(T$40/$AC$40)^3 -> 0.40673828 | U45: =3*(U$40/$AC$40)^2-2*(U$40/$AC$40)^3 -> 0.5 | ... AC45: =3*(AC$40/$AC$40)^2-2*(AC$40/$AC$40)^3 -> 1
B46: Net income | C46: ₹ bn | D46: =Data!D7/100 -> 7.115 | E46: =Data!D8/100 -> 11.301 | F46: =Data!D9/100 -> 14.042 | G46: =Data!D10/100 -> 15.014 | H46: =Data!D11/100 -> 9.73 | I46: =Data!D12/100 -> 21.73 | J46: =Data!D13/100 -> 32.5 | K46: =Data!D14/100 -> 34.96 | L46: =Data!D15/100 -> 33.37 | M46: =Data!D16/100 -> 50.73 | N46: =N41*N44 -> 68.86961 | O46: =O41*O44 -> 80.965378 | P46: =P41*P44 -> 94.702874 | Q46: =Q41*Q44 -> 110.59046 | R46: =R41*R44 -> 128.60212 | S46: =S41*S44 -> 148.6049 | T46: =T41*T44 -> 170.35003 | U46: =U41*U44 -> 193.48074 | ... AC46: =AC41*AC44 -> 387.87154
B47: Net income growth | C47: % | E47: =IF(D46=0,0,E46/D46-1) -> 0.5883345 | F47: =IF(E46=0,0,F46/E46-1) -> 0.24254491 | G47: =IF(F46=0,0,G46/F46-1) -> 0.069220909 | H47: =IF(G46=0,0,H46/G46-1) -> -0.35193819 | I47: =IF(H46=0,0,I46/H46-1) -> 1.2332991 | J47: =IF(I46=0,0,J46/I46-1) -> 0.49562816 | K47: =IF(J46=0,0,K46/J46-1) -> 0.075692308 | L47: =IF(K46=0,0,L46/K46-1) -> -0.045480549 | ... AC47: =IF(AB46=0,0,AC46/AB46-1) -> 0.069360403
B49: 3 DISCOUNTING (cash flow to equity = net income)
B50: Share of fiscal year counted | C50: share | N50: =IF(N$40=1,StubFraction,1) -> 0.49589041 | O50: =IF(O$40=1,StubFraction,1) -> 1 | P50: =IF(P$40=1,StubFraction,1) -> 1 | Q50: =IF(Q$40=1,StubFraction,1) -> 1 | R50: =IF(R$40=1,StubFraction,1) -> 1 | S50: =IF(S$40=1,StubFraction,1) -> 1 | T50: =IF(T$40=1,StubFraction,1) -> 1 | U50: =IF(U$40=1,StubFraction,1) -> 1 | ... AC50: =IF(AC$40=1,StubFraction,1) -> 1
...

Sheet Data
B2: Titan Company Ltd (NSE: TITAN): source data & notes
B3: Blue = hard-coded source data. ₹ crore; fiscal years end 31 March (2026 = Apr-2025 to Mar-2026).
B5: HISTORICAL FINANCIALS, CONSOLIDATED (₹ crore)
B6: Fiscal year | C6: Revenue | D6: Net income | E6: Net margin | F6: Revenue growth | G6: NI growth
B7: 2017 | C7: 13382.1 | D7: 711.5 | E7: =IF(C7=0,0,D7/C7) -> 0.053168038
B8: 2018 | C8: 16156 | D8: 1130.1 | E8: =IF(C8=0,0,D8/C8) -> 0.069949245 | F8: =IF(C7=0,0,C8/C7-1) -> 0.20728436 | G8: =IF(D7=0,0,D8/D7-1) -> 0.5883345
B9: 2019 | C9: 19778.5 | D9: 1404.2 | E9: =IF(C9=0,0,D9/C9) -> 0.070996284 | F9: =IF(C8=0,0,C9/C8-1) -> 0.2242201 | G9: =IF(D8=0,0,D9/D8-1) -> 0.24254491
B10: 2020 | C10: 21051.5 | D10: 1501.4 | E10: =IF(C10=0,0,D10/C10) -> 0.071320333 | F10: =IF(C9=0,0,C10/C9-1) -> 0.064362818 | G10: =IF(D9=0,0,D10/D9-1) -> 0.069220909
B11: 2021 | C11: 21644 | D11: 973 | E11: =IF(C11=0,0,D11/C11) -> 0.044954722 | F11: =IF(C10=0,0,C11/C10-1) -> 0.028145263 | G11: =IF(D10=0,0,D11/D10-1) -> -0.35193819
B12: 2022 | C12: 28799 | D12: 2173 | E12: =IF(C12=0,0,D12/C12) -> 0.075454009 | F12: =IF(C11=0,0,C12/C11-1) -> 0.3305766 | G12: =IF(D11=0,0,D12/D11-1) -> 1.2332991
B13: 2023 | C13: 40575 | D13: 3250 | E13: =IF(C13=0,0,D13/C13) -> 0.080098583 | F13: =IF(C12=0,0,C13/C12-1) -> 0.40890309 | G13: =IF(D12=0,0,D13/D12-1) -> 0.49562816
B14: 2024 | C14: 51084 | D14: 3496 | E14: =IF(C14=0,0,D14/C14) -> 0.068436301 | F14: =IF(C13=0,0,C14/C13-1) -> 0.25900185 | G14: =IF(D13=0,0,D14/D13-1) -> 0.075692308
B15: 2025 | C15: 60456 | D15: 3337 | E15: =IF(C15=0,0,D15/C15) -> 0.055197168 | F15: =IF(C14=0,0,C15/C14-1) -> 0.18346253 | G15: =IF(D14=0,0,D15/D14-1) -> -0.045480549
B16: 2026 | C16: 87584 | D16: 5073 | E16: =IF(C16=0,0,D16/C16) -> 0.057921538 | F16: =IF(C15=0,0,C16/C15-1) -> 0.44872304 | G16: =IF(D15=0,0,D16/D15-1) -> 0.52022775
B17: Source: company filings (consolidated), via Alpha Spread and Screener.in, retrieved 26-Sep-2026. Revenue = revenue from operations; net income = profit attributable to shareholders.
B19: LATEST REPORTED QUARTER (₹ crore)
B20: Quarter | C20: Revenue | D20: Net income | E20: Net margin
B21: Q1 FY2027 (Apr–Jun 2026) | C21: 21356 | D21: 1777 | E21: =IF(C21=0,0,D21/C21) -> 0.083208466
B22: Q1 FY2026 (Apr–Jun 2025) | C22: 16523 | D22: 1091 | E22: =IF(C22=0,0,D22/C22) -> 0.066029171
B23: Source: Screener.in quarterly results (consolidated). The FY2027 estimate includes this reported Q1; the model values the stock as of the price date (1-Oct-2026) and counts the remaining 50% of FY2027.
B25: METHODOLOGY
B26: 1. Discounted earnings: each year's net income is treated as the cash flow to equity. Equity value = PV of net income + PV of terminal value + net adjustments (none). This is not a free-cash-flow DCF; see the FCFF DCF sheet.
B27: 2. Revenue: FY2026 actual (₹875.8 bn) grows 17.2%, 17.6% and 17.0% in FY2027–FY2029 (analyst estimates), then fades on an S-curve from 17.04% to 6.95% by FY2042. The fade from FY2030 is my own assumption: it replaces the analysts' 7.2% estimate for FY2030. CAGR FY2026–FY2042: 12.6%.
B28: 3. Net margin: fades on an S-curve (weight 3x² – 2x³, x = t/16) from 6.71% to 6.63% by FY2042.
B29: 4. Timing: valuation date = price date (1-Oct-2026). The remaining 50% of FY2027 net income is counted; cash flows are discounted to each 31-March year-end (0.50, 1.50, … years).
B30: 5. Discount rate: 10.26% cost of equity. Explicit forecast: FY2028–FY2042 (15 years) plus the FY2027 stub.
B31: 6. Terminal value: FY2042 net income × 26.52x exit P/E, discounted with the FY2042 factor.
B32: 7. Value per share: equity value / 890 mn diluted shares = ₹4,057.51, 10.1% below the ₹4,515.70 market price (NSE close, 1-Oct-2026).
B35: SOURCES
B36: Alpha Spread: TITAN DCF base case (forecast assumptions to FY2029, cost of equity, exit multiple), retrieved 26-Sep-2026
B37: Screener.in: Titan Company consolidated financials
... B39: For education and analysis only; not investment advice.
